<mujoco model="hilly_light_aquarium">
  <compiler boundmass="1.0000000000000001e-05" boundinertia="9.9999999999999994e-12" coordinate="local" angle="radian" eulerseq="xyz"/>
  <option timestep="0.002" gravity="0 0 0" density="1000" viscosity="0.00089999999999999998" integrator="implicit" cone="elliptic" noslip_iterations="5" noslip_tolerance="0">
    <flag contact="disable"/>
  </option>
  <visual>
    <headlight ambient="0.29999999999999999 0.29999999999999999 0.29999999999999999" diffuse="0.59999999999999998 0.59999999999999998 0.59999999999999998" specular="0 0 0"/>
    <map znear="0.01"/>
    <scale forcewidth="0.01" contactwidth="0.059999999999999998" contactheight="0.01" jointwidth="0.01" framelength="0.29999999999999999" framewidth="0.01"/>
  </visual>
  <default>
    <default class="/">
      <geom contype="1" conaffinity="0"/>
    </default>
    <default class="unnamed_model/"/>
    <default class="morphology/">
      <geom contype="1" conaffinity="0"/>
    </default>
  </default>
  <asset>
    <texture name="//unnamed_texture_0" type="skybox" builtin="flat" rgb1="1 1 1" rgb2="1 1 1" width="200" height="200"/>
    <texture name="light_gradient_ground_plane" type="2d" file="lightmap_0-a4f658a06a15173588494d629790fe500db35b13.png"/>
    <material name="groundplane" class="/" texture="light_gradient_ground_plane" reflectance="0"/>
    <hfield name="heightmap" file="heightmap_0-91fcc20c0c8c7a3740585df582e9b54536c2b6da.png" size="10 10 1.5 0.5"/>
  </asset>
  <worldbody>
    <camera name="top_camera" class="/" pos="-1 -1 20" quat="1 0 0 0"/>
    <light name="//unnamed_light_0" class="/" directional="true" castshadow="true" pos="0 0 20" dir="0 0 -0.5" diffuse="0.10000000000000001 0.10000000000000001 0.10000000000000001"/>
    <geom name="height_map_geom" class="/" type="hfield" conaffinity="1" material="groundplane" hfield="heightmap"/>
    <geom name="north_wall" class="/" type="box" conaffinity="1" size="10 0.10000000000000001 2.1000000000000001" rgba="0.45098039215686275 0.57647058823529407 0.70196078431372544 0.19607843137254902" pos="0 10.1 1.6000000000000001"/>
    <geom name="south_wall" class="/" type="box" conaffinity="1" size="10 0.10000000000000001 2.1000000000000001" rgba="0.45098039215686275 0.57647058823529407 0.70196078431372544 0.19607843137254902" pos="0 -10.1 1.6000000000000001"/>
    <geom name="east_wall" class="/" type="box" conaffinity="1" size="0.10000000000000001 10.199999999999999 2.1000000000000001" rgba="0.45098039215686275 0.57647058823529407 0.70196078431372544 0.19607843137254902" pos="-10.1 0 1.6000000000000001"/>
    <geom name="west_wall" class="/" type="box" conaffinity="1" size="0.10000000000000001 10.199999999999999 2.1000000000000001" rgba="0.45098039215686275 0.57647058823529407 0.70196078431372544 0.19607843137254902" pos="10.1 0 1.6000000000000001"/>
    <body name="unnamed_model/">
      <geom name="unnamed_model//unnamed_geom_0" class="unnamed_model/" type="sphere" size="0.10000000000000001" rgba="100 100 100 0.5"/>
    </body>
    <body name="morphology/">
      <freejoint name="morphology/"/>
      <body name="morphology//unnamed_body_0">
        <body name="morphology/torso" pos="0 0 0" euler="0 0 0">
          <geom name="morphology/torso_body" class="morphology/" type="capsule" size="0.10000000000000001 0.20000000000000001" rgba="100 0 0 0.5" friction="0.10000000000000001 0.10000000000000001 0.10000000000000001" density="1000" pos="0 0 0" euler="0 1.5707963267948966 0"/>
          <body name="morphology/right_pectoral_fin" pos="-0.20000000000000001 -0.10000000000000001 0" euler="0 0 0">
            <body name="morphology/right_pectoral_fin_segment_0" pos="0.040000000000000001 0 0" euler="0 0 0">
              <geom name="morphology/right_pectoral_fin_segment_0_capsule" class="morphology/" type="capsule" size="0.018000000000000002 0.20000000000000001" rgba="100 0 0 0.5" density="1000" pos="0 -0.21800000000000003 0" euler="1.5707963267948966 0 0"/>
              <joint name="morphology/right_pectoral_fin_segment_0_x_axis" class="morphology/" type="hinge" axis="1 0 0" limited="true" stiffness="0.5" range="-1.5707963267948966 1.5707963267948966" damping="0.5"/>
              <joint name="morphology/right_pectoral_fin_segment_0_z_axis" class="morphology/" type="hinge" axis="0 0 1" limited="true" stiffness="0.5" range="-0.078539816339744828 0.078539816339744828" damping="0.5"/>
              <site name="morphology/right_pectoral_fin_segment_0_tendon_site" class="morphology/" type="sphere" size="0.0001 0.0001 0.0001" pos="0 -0.21800000000000003 0" euler="0 0 0"/>
            </body>
            <body name="morphology/right_pectoral_fin_segment_1" pos="0.080000000000000002 0 0" euler="0 0 0">
              <geom name="morphology/right_pectoral_fin_segment_1_capsule" class="morphology/" type="capsule" size="0.018000000000000002 0.1367544467966324" rgba="100 0 0 0.5" density="1000" pos="0 -0.15475444679663242 0" euler="1.5707963267948966 0 0"/>
              <joint name="morphology/right_pectoral_fin_segment_1_x_axis" class="morphology/" type="hinge" axis="1 0 0" limited="true" stiffness="0.5" range="-1.5707963267948966 1.5707963267948966" damping="0.5"/>
              <joint name="morphology/right_pectoral_fin_segment_1_z_axis" class="morphology/" type="hinge" axis="0 0 1" limited="true" stiffness="0.5" range="-0.078539816339744828 0.078539816339744828" damping="0.5"/>
              <site name="morphology/right_pectoral_fin_segment_1_tendon_site" class="morphology/" type="sphere" size="0.0001 0.0001 0.0001" pos="0 -0.15475444679663242 0" euler="0 0 0"/>
            </body>
            <body name="morphology/right_pectoral_fin_segment_2" pos="0.12 0 0" euler="0 0 0">
              <geom name="morphology/right_pectoral_fin_segment_2_capsule" class="morphology/" type="capsule" size="0.018000000000000002 0.11055728090000842" rgba="100 0 0 0.5" density="1000" pos="0 -0.12855728090000842 0" euler="1.5707963267948966 0 0"/>
              <joint name="morphology/right_pectoral_fin_segment_2_x_axis" class="morphology/" type="hinge" axis="1 0 0" limited="true" stiffness="0.5" range="-1.5707963267948966 1.5707963267948966" damping="0.5"/>
              <joint name="morphology/right_pectoral_fin_segment_2_z_axis" class="morphology/" type="hinge" axis="0 0 1" limited="true" stiffness="0.5" range="-0.078539816339744828 0.078539816339744828" damping="0.5"/>
              <site name="morphology/right_pectoral_fin_segment_2_tendon_site" class="morphology/" type="sphere" size="0.0001 0.0001 0.0001" pos="0 -0.12855728090000842 0" euler="0 0 0"/>
            </body>
            <body name="morphology/right_pectoral_fin_segment_3" pos="0.16 0 0" euler="0 0 0">
              <geom name="morphology/right_pectoral_fin_segment_3_capsule" class="morphology/" type="capsule" size="0.018000000000000002 0.090455488498966785" rgba="100 0 0 0.5" density="1000" pos="0 -0.10845548849896679 0" euler="1.5707963267948966 0 0"/>
              <joint name="morphology/right_pectoral_fin_segment_3_x_axis" class="morphology/" type="hinge" axis="1 0 0" limited="true" stiffness="0.5" range="-1.5707963267948966 1.5707963267948966" damping="0.5"/>
              <joint name="morphology/right_pectoral_fin_segment_3_z_axis" class="morphology/" type="hinge" axis="0 0 1" limited="true" stiffness="0.5" range="-0.078539816339744828 0.078539816339744828" damping="0.5"/>
              <site name="morphology/right_pectoral_fin_segment_3_tendon_site" class="morphology/" type="sphere" size="0.0001 0.0001 0.0001" pos="0 -0.10845548849896679 0" euler="0 0 0"/>
            </body>
            <body name="morphology/right_pectoral_fin_segment_4" pos="0.20000000000000001 0 0" euler="0 0 0">
              <geom name="morphology/right_pectoral_fin_segment_4_capsule" class="morphology/" type="capsule" size="0.018000000000000002 0.073508893593264818" rgba="100 0 0 0.5" density="1000" pos="0 -0.09150889359326482 0" euler="1.5707963267948966 0 0"/>
              <joint name="morphology/right_pectoral_fin_segment_4_x_axis" class="morphology/" type="hinge" axis="1 0 0" limited="true" stiffness="0.5" range="-1.5707963267948966 1.5707963267948966" damping="0.5"/>
              <joint name="morphology/right_pectoral_fin_segment_4_z_axis" class="morphology/" type="hinge" axis="0 0 1" limited="true" stiffness="0.5" range="-0.078539816339744828 0.078539816339744828" damping="0.5"/>
              <site name="morphology/right_pectoral_fin_segment_4_tendon_site" class="morphology/" type="sphere" size="0.0001 0.0001 0.0001" pos="0 -0.09150889359326482 0" euler="0 0 0"/>
            </body>
            <body name="morphology/right_pectoral_fin_segment_5" pos="0.24000000000000002 0 0" euler="0 0 0">
              <geom name="morphology/right_pectoral_fin_segment_5_capsule" class="morphology/" type="capsule" size="0.018000000000000002 0.05857864376269048" rgba="100 0 0 0.5" density="1000" pos="0 -0.076578643762690482 0" euler="1.5707963267948966 0 0"/>
              <joint name="morphology/right_pectoral_fin_segment_5_x_axis" class="morphology/" type="hinge" axis="1 0 0" limited="true" stiffness="0.5" range="-1.5707963267948966 1.5707963267948966" damping="0.5"/>
              <joint name="morphology/right_pectoral_fin_segment_5_z_axis" class="morphology/" type="hinge" axis="0 0 1" limited="true" stiffness="0.5" range="-0.078539816339744828 0.078539816339744828" damping="0.5"/>
              <site name="morphology/right_pectoral_fin_segment_5_tendon_site" class="morphology/" type="sphere" size="0.0001 0.0001 0.0001" pos="0 -0.076578643762690482 0" euler="0 0 0"/>
            </body>
            <body name="morphology/right_pectoral_fin_segment_6" pos="0.28000000000000003 0 0" euler="0 0 0">
              <geom name="morphology/right_pectoral_fin_segment_6_capsule" class="morphology/" type="capsule" size="0.018000000000000002 0.045080666151703308" rgba="100 0 0 0.5" density="1000" pos="0 -0.06308066615170331 0" euler="1.5707963267948966 0 0"/>
              <joint name="morphology/right_pectoral_fin_segment_6_x_axis" class="morphology/" type="hinge" axis="1 0 0" limited="true" stiffness="0.5" range="-1.5707963267948966 1.5707963267948966" damping="0.5"/>
              <joint name="morphology/right_pectoral_fin_segment_6_z_axis" class="morphology/" type="hinge" axis="0 0 1" limited="true" stiffness="0.5" range="-0.078539816339744828 0.078539816339744828" damping="0.5"/>
              <site name="morphology/right_pectoral_fin_segment_6_tendon_site" class="morphology/" type="sphere" size="0.0001 0.0001 0.0001" pos="0 -0.06308066615170331 0" euler="0 0 0"/>
            </body>
            <body name="morphology/right_pectoral_fin_segment_7" pos="0.32000000000000001 0 0" euler="0 0 0">
              <geom name="morphology/right_pectoral_fin_segment_7_capsule" class="morphology/" type="capsule" size="0.018000000000000002 0.032667994693184876" rgba="100 0 0 0.5" density="1000" pos="0 -0.050667994693184878 0" euler="1.5707963267948966 0 0"/>
              <joint name="morphology/right_pectoral_fin_segment_7_x_axis" class="morphology/" type="hinge" axis="1 0 0" limited="true" stiffness="0.5" range="-1.5707963267948966 1.5707963267948966" damping="0.5"/>
              <joint name="morphology/right_pectoral_fin_segment_7_z_axis" class="morphology/" type="hinge" axis="0 0 1" limited="true" stiffness="0.5" range="-0.078539816339744828 0.078539816339744828" damping="0.5"/>
              <site name="morphology/right_pectoral_fin_segment_7_tendon_site" class="morphology/" type="sphere" size="0.0001 0.0001 0.0001" pos="0 -0.050667994693184878 0" euler="0 0 0"/>
            </body>
            <body name="morphology/right_pectoral_fin_segment_8" pos="0.35999999999999999 0 0" euler="0 0 0">
              <geom name="morphology/right_pectoral_fin_segment_8_capsule" class="morphology/" type="capsule" size="0.018000000000000002 0.021114561800016834" rgba="100 0 0 0.5" density="1000" pos="0 -0.039114561800016837 0" euler="1.5707963267948966 0 0"/>
              <joint name="morphology/right_pectoral_fin_segment_8_x_axis" class="morphology/" type="hinge" axis="1 0 0" limited="true" stiffness="0.5" range="-1.5707963267948966 1.5707963267948966" damping="0.5"/>
              <joint name="morphology/right_pectoral_fin_segment_8_z_axis" class="morphology/" type="hinge" axis="0 0 1" limited="true" stiffness="0.5" range="-0.078539816339744828 0.078539816339744828" damping="0.5"/>
              <site name="morphology/right_pectoral_fin_segment_8_tendon_site" class="morphology/" type="sphere" size="0.0001 0.0001 0.0001" pos="0 -0.039114561800016837 0" euler="0 0 0"/>
            </body>
            <body name="morphology/right_pectoral_fin_segment_9" pos="0.39999999999999997 0 0" euler="0 0 0">
              <geom name="morphology/right_pectoral_fin_segment_9_capsule" class="morphology/" type="capsule" size="0.018000000000000002 0.010263340389897235" rgba="100 0 0 0.5" density="1000" pos="0 -0.028263340389897237 0" euler="1.5707963267948966 0 0"/>
              <joint name="morphology/right_pectoral_fin_segment_9_x_axis" class="morphology/" type="hinge" axis="1 0 0" limited="true" stiffness="0.5" range="-1.5707963267948966 1.5707963267948966" damping="0.5"/>
              <joint name="morphology/right_pectoral_fin_segment_9_z_axis" class="morphology/" type="hinge" axis="0 0 1" limited="true" stiffness="0.5" range="-0.078539816339744828 0.078539816339744828" damping="0.5"/>
              <site name="morphology/right_pectoral_fin_segment_9_tendon_site" class="morphology/" type="sphere" size="0.0001 0.0001 0.0001" pos="0 -0.028263340389897237 0" euler="0 0 0"/>
            </body>
          </body>
          <body name="morphology/left_pectoral_fin" pos="-0.20000000000000001 0.10000000000000001 0" euler="0 0 0">
            <body name="morphology/left_pectoral_fin_segment_0" pos="0.040000000000000001 0 0" euler="0 0 0">
              <geom name="morphology/left_pectoral_fin_segment_0_capsule" class="morphology/" type="capsule" size="0.018000000000000002 0.20000000000000001" rgba="100 0 0 0.5" density="1000" pos="0 0.21800000000000003 0" euler="1.5707963267948966 0 0"/>
              <joint name="morphology/left_pectoral_fin_segment_0_x_axis" class="morphology/" type="hinge" axis="1 0 0" limited="true" stiffness="0.5" range="-1.5707963267948966 1.5707963267948966" damping="0.5"/>
              <joint name="morphology/left_pectoral_fin_segment_0_z_axis" class="morphology/" type="hinge" axis="0 0 1" limited="true" stiffness="0.5" range="-0.078539816339744828 0.078539816339744828" damping="0.5"/>
              <site name="morphology/left_pectoral_fin_segment_0_tendon_site" class="morphology/" type="sphere" size="0.0001 0.0001 0.0001" pos="0 0.21800000000000003 0" euler="0 0 0"/>
            </body>
            <body name="morphology/left_pectoral_fin_segment_1" pos="0.080000000000000002 0 0" euler="0 0 0">
              <geom name="morphology/left_pectoral_fin_segment_1_capsule" class="morphology/" type="capsule" size="0.018000000000000002 0.1367544467966324" rgba="100 0 0 0.5" density="1000" pos="0 0.15475444679663242 0" euler="1.5707963267948966 0 0"/>
              <joint name="morphology/left_pectoral_fin_segment_1_x_axis" class="morphology/" type="hinge" axis="1 0 0" limited="true" stiffness="0.5" range="-1.5707963267948966 1.5707963267948966" damping="0.5"/>
              <joint name="morphology/left_pectoral_fin_segment_1_z_axis" class="morphology/" type="hinge" axis="0 0 1" limited="true" stiffness="0.5" range="-0.078539816339744828 0.078539816339744828" damping="0.5"/>
              <site name="morphology/left_pectoral_fin_segment_1_tendon_site" class="morphology/" type="sphere" size="0.0001 0.0001 0.0001" pos="0 0.15475444679663242 0" euler="0 0 0"/>
            </body>
            <body name="morphology/left_pectoral_fin_segment_2" pos="0.12 0 0" euler="0 0 0">
              <geom name="morphology/left_pectoral_fin_segment_2_capsule" class="morphology/" type="capsule" size="0.018000000000000002 0.11055728090000842" rgba="100 0 0 0.5" density="1000" pos="0 0.12855728090000842 0" euler="1.5707963267948966 0 0"/>
              <joint name="morphology/left_pectoral_fin_segment_2_x_axis" class="morphology/" type="hinge" axis="1 0 0" limited="true" stiffness="0.5" range="-1.5707963267948966 1.5707963267948966" damping="0.5"/>
              <joint name="morphology/left_pectoral_fin_segment_2_z_axis" class="morphology/" type="hinge" axis="0 0 1" limited="true" stiffness="0.5" range="-0.078539816339744828 0.078539816339744828" damping="0.5"/>
              <site name="morphology/left_pectoral_fin_segment_2_tendon_site" class="morphology/" type="sphere" size="0.0001 0.0001 0.0001" pos="0 0.12855728090000842 0" euler="0 0 0"/>
            </body>
            <body name="morphology/left_pectoral_fin_segment_3" pos="0.16 0 0" euler="0 0 0">
              <geom name="morphology/left_pectoral_fin_segment_3_capsule" class="morphology/" type="capsule" size="0.018000000000000002 0.090455488498966785" rgba="100 0 0 0.5" density="1000" pos="0 0.10845548849896679 0" euler="1.5707963267948966 0 0"/>
              <joint name="morphology/left_pectoral_fin_segment_3_x_axis" class="morphology/" type="hinge" axis="1 0 0" limited="true" stiffness="0.5" range="-1.5707963267948966 1.5707963267948966" damping="0.5"/>
              <joint name="morphology/left_pectoral_fin_segment_3_z_axis" class="morphology/" type="hinge" axis="0 0 1" limited="true" stiffness="0.5" range="-0.078539816339744828 0.078539816339744828" damping="0.5"/>
              <site name="morphology/left_pectoral_fin_segment_3_tendon_site" class="morphology/" type="sphere" size="0.0001 0.0001 0.0001" pos="0 0.10845548849896679 0" euler="0 0 0"/>
            </body>
            <body name="morphology/left_pectoral_fin_segment_4" pos="0.20000000000000001 0 0" euler="0 0 0">
              <geom name="morphology/left_pectoral_fin_segment_4_capsule" class="morphology/" type="capsule" size="0.018000000000000002 0.073508893593264818" rgba="100 0 0 0.5" density="1000" pos="0 0.09150889359326482 0" euler="1.5707963267948966 0 0"/>
              <joint name="morphology/left_pectoral_fin_segment_4_x_axis" class="morphology/" type="hinge" axis="1 0 0" limited="true" stiffness="0.5" range="-1.5707963267948966 1.5707963267948966" damping="0.5"/>
              <joint name="morphology/left_pectoral_fin_segment_4_z_axis" class="morphology/" type="hinge" axis="0 0 1" limited="true" stiffness="0.5" range="-0.078539816339744828 0.078539816339744828" damping="0.5"/>
              <site name="morphology/left_pectoral_fin_segment_4_tendon_site" class="morphology/" type="sphere" size="0.0001 0.0001 0.0001" pos="0 0.09150889359326482 0" euler="0 0 0"/>
            </body>
            <body name="morphology/left_pectoral_fin_segment_5" pos="0.24000000000000002 0 0" euler="0 0 0">
              <geom name="morphology/left_pectoral_fin_segment_5_capsule" class="morphology/" type="capsule" size="0.018000000000000002 0.05857864376269048" rgba="100 0 0 0.5" density="1000" pos="0 0.076578643762690482 0" euler="1.5707963267948966 0 0"/>
              <joint name="morphology/left_pectoral_fin_segment_5_x_axis" class="morphology/" type="hinge" axis="1 0 0" limited="true" stiffness="0.5" range="-1.5707963267948966 1.5707963267948966" damping="0.5"/>
              <joint name="morphology/left_pectoral_fin_segment_5_z_axis" class="morphology/" type="hinge" axis="0 0 1" limited="true" stiffness="0.5" range="-0.078539816339744828 0.078539816339744828" damping="0.5"/>
              <site name="morphology/left_pectoral_fin_segment_5_tendon_site" class="morphology/" type="sphere" size="0.0001 0.0001 0.0001" pos="0 0.076578643762690482 0" euler="0 0 0"/>
            </body>
            <body name="morphology/left_pectoral_fin_segment_6" pos="0.28000000000000003 0 0" euler="0 0 0">
              <geom name="morphology/left_pectoral_fin_segment_6_capsule" class="morphology/" type="capsule" size="0.018000000000000002 0.045080666151703308" rgba="100 0 0 0.5" density="1000" pos="0 0.06308066615170331 0" euler="1.5707963267948966 0 0"/>
              <joint name="morphology/left_pectoral_fin_segment_6_x_axis" class="morphology/" type="hinge" axis="1 0 0" limited="true" stiffness="0.5" range="-1.5707963267948966 1.5707963267948966" damping="0.5"/>
              <joint name="morphology/left_pectoral_fin_segment_6_z_axis" class="morphology/" type="hinge" axis="0 0 1" limited="true" stiffness="0.5" range="-0.078539816339744828 0.078539816339744828" damping="0.5"/>
              <site name="morphology/left_pectoral_fin_segment_6_tendon_site" class="morphology/" type="sphere" size="0.0001 0.0001 0.0001" pos="0 0.06308066615170331 0" euler="0 0 0"/>
            </body>
            <body name="morphology/left_pectoral_fin_segment_7" pos="0.32000000000000001 0 0" euler="0 0 0">
              <geom name="morphology/left_pectoral_fin_segment_7_capsule" class="morphology/" type="capsule" size="0.018000000000000002 0.032667994693184876" rgba="100 0 0 0.5" density="1000" pos="0 0.050667994693184878 0" euler="1.5707963267948966 0 0"/>
              <joint name="morphology/left_pectoral_fin_segment_7_x_axis" class="morphology/" type="hinge" axis="1 0 0" limited="true" stiffness="0.5" range="-1.5707963267948966 1.5707963267948966" damping="0.5"/>
              <joint name="morphology/left_pectoral_fin_segment_7_z_axis" class="morphology/" type="hinge" axis="0 0 1" limited="true" stiffness="0.5" range="-0.078539816339744828 0.078539816339744828" damping="0.5"/>
              <site name="morphology/left_pectoral_fin_segment_7_tendon_site" class="morphology/" type="sphere" size="0.0001 0.0001 0.0001" pos="0 0.050667994693184878 0" euler="0 0 0"/>
            </body>
            <body name="morphology/left_pectoral_fin_segment_8" pos="0.35999999999999999 0 0" euler="0 0 0">
              <geom name="morphology/left_pectoral_fin_segment_8_capsule" class="morphology/" type="capsule" size="0.018000000000000002 0.021114561800016834" rgba="100 0 0 0.5" density="1000" pos="0 0.039114561800016837 0" euler="1.5707963267948966 0 0"/>
              <joint name="morphology/left_pectoral_fin_segment_8_x_axis" class="morphology/" type="hinge" axis="1 0 0" limited="true" stiffness="0.5" range="-1.5707963267948966 1.5707963267948966" damping="0.5"/>
              <joint name="morphology/left_pectoral_fin_segment_8_z_axis" class="morphology/" type="hinge" axis="0 0 1" limited="true" stiffness="0.5" range="-0.078539816339744828 0.078539816339744828" damping="0.5"/>
              <site name="morphology/left_pectoral_fin_segment_8_tendon_site" class="morphology/" type="sphere" size="0.0001 0.0001 0.0001" pos="0 0.039114561800016837 0" euler="0 0 0"/>
            </body>
            <body name="morphology/left_pectoral_fin_segment_9" pos="0.39999999999999997 0 0" euler="0 0 0">
              <geom name="morphology/left_pectoral_fin_segment_9_capsule" class="morphology/" type="capsule" size="0.018000000000000002 0.010263340389897235" rgba="100 0 0 0.5" density="1000" pos="0 0.028263340389897237 0" euler="1.5707963267948966 0 0"/>
              <joint name="morphology/left_pectoral_fin_segment_9_x_axis" class="morphology/" type="hinge" axis="1 0 0" limited="true" stiffness="0.5" range="-1.5707963267948966 1.5707963267948966" damping="0.5"/>
              <joint name="morphology/left_pectoral_fin_segment_9_z_axis" class="morphology/" type="hinge" axis="0 0 1" limited="true" stiffness="0.5" range="-0.078539816339744828 0.078539816339744828" damping="0.5"/>
              <site name="morphology/left_pectoral_fin_segment_9_tendon_site" class="morphology/" type="sphere" size="0.0001 0.0001 0.0001" pos="0 0.028263340389897237 0" euler="0 0 0"/>
            </body>
          </body>
        </body>
        <body name="morphology/tail" pos="0.30000000000000004 0 0" euler="0 0 0">
          <body name="morphology/tail_segment_0" pos="0 0 0" euler="0 0 0">
            <geom name="morphology/tail_segment_0_capsule" class="morphology/" type="capsule" size="0.01 0.10000000000000001" rgba="100 0 0 0.5" density="1000" pos="0.11 0 0" euler="0 1.5707963267948966 0"/>
            <joint name="morphology/tail_segment_0_z_axis" class="morphology/" type="hinge" axis="0 0 1" limited="true" stiffness="0.01" range="-0.78539816339744828 0.78539816339744828" damping="1"/>
            <joint name="morphology/tail_segment_0_y_axis" class="morphology/" type="hinge" axis="0 1 0" limited="true" stiffness="0.01" range="-0.78539816339744828 0.78539816339744828" damping="1"/>
            <body name="morphology/tail_segment_1" pos="0.22 0 0" euler="0 0 0">
              <geom name="morphology/tail_segment_1_capsule" class="morphology/" type="capsule" size="0.01 0.10000000000000001" rgba="100 0 0 0.5" density="1000" pos="0.11 0 0" euler="0 1.5707963267948966 0"/>
              <joint name="morphology/tail_segment_1_z_axis" class="morphology/" type="hinge" axis="0 0 1" limited="true" stiffness="0.01" range="-0.78539816339744828 0.78539816339744828" damping="1"/>
              <joint name="morphology/tail_segment_1_y_axis" class="morphology/" type="hinge" axis="0 1 0" limited="true" stiffness="0.01" range="-0.78539816339744828 0.78539816339744828" damping="1"/>
            </body>
          </body>
        </body>
      </body>
    </body>
  </worldbody>
  <tendon>
    <spatial name="morphology/right_pectoral_fin_tendon_right" class="morphology/" limited="true" range="-18.783929301400175 19.163402620620381" width="0.0050000000000000001" stiffness="1000" damping="1">
      <site site="morphology/right_pectoral_fin_segment_0_tendon_site"/>
      <site site="morphology/right_pectoral_fin_segment_1_tendon_site"/>
      <site site="morphology/right_pectoral_fin_segment_2_tendon_site"/>
      <site site="morphology/right_pectoral_fin_segment_3_tendon_site"/>
      <site site="morphology/right_pectoral_fin_segment_4_tendon_site"/>
      <site site="morphology/right_pectoral_fin_segment_5_tendon_site"/>
      <site site="morphology/right_pectoral_fin_segment_6_tendon_site"/>
      <site site="morphology/right_pectoral_fin_segment_7_tendon_site"/>
      <site site="morphology/right_pectoral_fin_segment_8_tendon_site"/>
      <site site="morphology/right_pectoral_fin_segment_9_tendon_site"/>
    </spatial>
    <spatial name="morphology/left_pectoral_fin_tendon_left" class="morphology/" limited="true" range="-18.783929301400175 19.163402620620381" width="0.0050000000000000001" stiffness="1000" damping="1">
      <site site="morphology/left_pectoral_fin_segment_0_tendon_site"/>
      <site site="morphology/left_pectoral_fin_segment_1_tendon_site"/>
      <site site="morphology/left_pectoral_fin_segment_2_tendon_site"/>
      <site site="morphology/left_pectoral_fin_segment_3_tendon_site"/>
      <site site="morphology/left_pectoral_fin_segment_4_tendon_site"/>
      <site site="morphology/left_pectoral_fin_segment_5_tendon_site"/>
      <site site="morphology/left_pectoral_fin_segment_6_tendon_site"/>
      <site site="morphology/left_pectoral_fin_segment_7_tendon_site"/>
      <site site="morphology/left_pectoral_fin_segment_8_tendon_site"/>
      <site site="morphology/left_pectoral_fin_segment_9_tendon_site"/>
    </spatial>
  </tendon>
  <actuator>
    <position name="morphology/tail_segment_0_z_axis_actuator" class="morphology/" ctrllimited="true" ctrlrange="-0.78539816339744828 0.78539816339744828" joint="morphology/tail_segment_0_z_axis" kp="100"/>
    <position name="morphology/tail_segment_0_y_axis_actuator" class="morphology/" ctrllimited="true" ctrlrange="-0.78539816339744828 0.78539816339744828" joint="morphology/tail_segment_0_y_axis" kp="100"/>
    <position name="morphology/tail_segment_1_z_axis_actuator" class="morphology/" ctrllimited="true" ctrlrange="-0.78539816339744828 0.78539816339744828" joint="morphology/tail_segment_1_z_axis" kp="100"/>
    <position name="morphology/tail_segment_1_y_axis_actuator" class="morphology/" ctrllimited="true" ctrlrange="-0.78539816339744828 0.78539816339744828" joint="morphology/tail_segment_1_y_axis" kp="100"/>
    <position name="morphology/right_pectoral_fin_actuator_x" class="morphology/" ctrllimited="true" ctrlrange="-1.5707963267948966 1.5707963267948966" joint="morphology/right_pectoral_fin_segment_0_x_axis" kp="100"/>
    <position name="morphology/right_pectoral_fin_actuator_z" class="morphology/" ctrllimited="true" ctrlrange="-1.5707963267948966 1.5707963267948966" joint="morphology/right_pectoral_fin_segment_0_z_axis" kp="100"/>
    <position name="morphology/left_pectoral_fin_actuator_x" class="morphology/" ctrllimited="true" ctrlrange="-1.5707963267948966 1.5707963267948966" joint="morphology/left_pectoral_fin_segment_0_x_axis" kp="100"/>
    <position name="morphology/left_pectoral_fin_actuator_z" class="morphology/" ctrllimited="true" ctrlrange="-1.5707963267948966 1.5707963267948966" joint="morphology/left_pectoral_fin_segment_0_z_axis" kp="100"/>
  </actuator>
  <sensor>
    <actuatorfrc name="morphology/right_pectoral_fin_force_sensor_x" actuator="morphology/right_pectoral_fin_actuator_x"/>
    <actuatorfrc name="morphology/right_pectoral_fin_force_sensor_z" actuator="morphology/right_pectoral_fin_actuator_z"/>
    <actuatorfrc name="morphology/left_pectoral_fin_force_sensor_x" actuator="morphology/left_pectoral_fin_actuator_x"/>
    <actuatorfrc name="morphology/left_pectoral_fin_force_sensor_z" actuator="morphology/left_pectoral_fin_actuator_z"/>
  </sensor>
</mujoco>
