<mujoco model="hilly_light_aquarium">
  <compiler boundmass="1.0000000000000001e-05" boundinertia="9.9999999999999994e-12" coordinate="local" angle="radian" eulerseq="xyz"/>
  <option timestep="0.002" gravity="0 0 0" density="1000" viscosity="0.00089999999999999998" integrator="implicit" cone="elliptic" noslip_iterations="5" noslip_tolerance="0">
    <flag contact="disable"/>
  </option>
  <visual>
    <headlight ambient="0.29999999999999999 0.29999999999999999 0.29999999999999999" diffuse="0.59999999999999998 0.59999999999999998 0.59999999999999998" specular="0 0 0"/>
    <map znear="0.01"/>
    <scale forcewidth="0.01" contactwidth="0.059999999999999998" contactheight="0.01" jointwidth="0.01" framelength="0.29999999999999999" framewidth="0.01"/>
  </visual>
  <default>
    <default class="/">
      <geom contype="1" conaffinity="0"/>
    </default>
    <default class="unnamed_model/"/>
    <default class="morphology/">
      <geom contype="1" conaffinity="0"/>
    </default>
  </default>
  <asset>
    <texture name="//unnamed_texture_0" type="skybox" builtin="flat" rgb1="1 1 1" rgb2="1 1 1" width="200" height="200"/>
    <texture name="groundplane" type="2d" builtin="checker" rgb1="0.20000000000000001 0.29999999999999999 0.40000000000000002" rgb2="0.10000000000000001 0.20000000000000001 0.29999999999999999" mark="edge" markrgb="0.80000000000000004 0.80000000000000004 0.80000000000000004" width="200" height="200"/>
    <material name="groundplane" class="/" texture="groundplane" texrepeat="2 2" texuniform="true" reflectance="0"/>
    <hfield name="heightmap" file="heightmap_0-91fcc20c0c8c7a3740585df582e9b54536c2b6da.png" size="10 10 1.5 0.5"/>
  </asset>
  <worldbody>
    <camera name="top_camera" class="/" pos="-1 -1 20" quat="1 0 0 0"/>
    <light name="//unnamed_light_0" class="/" directional="true" castshadow="true" pos="0 0 20" dir="0 0 -0.5" diffuse="0.10000000000000001 0.10000000000000001 0.10000000000000001"/>
    <geom name="height_map_geom" class="/" type="hfield" conaffinity="1" material="groundplane" hfield="heightmap"/>
    <geom name="north_wall" class="/" type="box" conaffinity="1" size="10 0.10000000000000001 2.1000000000000001" rgba="0.45098039215686275 0.57647058823529407 0.70196078431372544 0.19607843137254902" pos="0 10.1 1.6000000000000001"/>
    <geom name="south_wall" class="/" type="box" conaffinity="1" size="10 0.10000000000000001 2.1000000000000001" rgba="0.45098039215686275 0.57647058823529407 0.70196078431372544 0.19607843137254902" pos="0 -10.1 1.6000000000000001"/>
    <geom name="east_wall" class="/" type="box" conaffinity="1" size="0.10000000000000001 10.199999999999999 2.1000000000000001" rgba="0.45098039215686275 0.57647058823529407 0.70196078431372544 0.19607843137254902" pos="-10.1 0 1.6000000000000001"/>
    <geom name="west_wall" class="/" type="box" conaffinity="1" size="0.10000000000000001 10.199999999999999 2.1000000000000001" rgba="0.45098039215686275 0.57647058823529407 0.70196078431372544 0.19607843137254902" pos="10.1 0 1.6000000000000001"/>
    <body name="unnamed_model/">
      <geom name="unnamed_model//unnamed_geom_0" class="unnamed_model/" type="sphere" size="0.10000000000000001" rgba="100 100 100 0.5"/>
    </body>
    <body name="morphology/">
      <freejoint name="morphology/"/>
      <body name="morphology//unnamed_body_0">
        <body name="morphology/torso" pos="0 0 0" euler="0 0 0">
          <geom name="morphology/torso_body" class="morphology/" type="capsule" size="0.11111111111111112 0.22222222222222224" rgba="100 0 0 0.5" friction="0.10000000000000001 0.10000000000000001 0.10000000000000001" density="1000" pos="0 0 0" euler="0 1.5707963267948966 0"/>
          <body name="morphology/right_pectoral_fin" pos="-0.22222222222222224 -0.11111111111111112 0" euler="0 0 0">
            <body name="morphology/right_pectoral_fin_segment_0" pos="0.044444444444444446 0 0" euler="0 0 0">
              <geom name="morphology/right_pectoral_fin_segment_0_capsule" class="morphology/" type="capsule" size="0.02 0.22222222222222224" rgba="100 0 0 0.5" density="1000" pos="0 -0.24222222222222223 0" euler="1.5707963267948966 0 0"/>
              <joint name="morphology/right_pectoral_fin_segment_0_x_axis" class="morphology/" type="hinge" axis="1 0 0" limited="true" stiffness="0.5" range="-1.5707963267948966 1.5707963267948966" damping="0.5"/>
              <joint name="morphology/right_pectoral_fin_segment_0_z_axis" class="morphology/" type="hinge" axis="0 0 1" limited="true" stiffness="0.5" range="-0.078539816339744828 0.078539816339744828" damping="0.5"/>
              <site name="morphology/right_pectoral_fin_segment_0_tendon_site" class="morphology/" type="sphere" size="0.0001 0.0001 0.0001" pos="0 -0.24222222222222223 0" euler="0 0 0"/>
            </body>
            <body name="morphology/right_pectoral_fin_segment_1" pos="0.088888888888888892 0 0" euler="0 0 0">
              <geom name="morphology/right_pectoral_fin_segment_1_capsule" class="morphology/" type="capsule" size="0.02 0.15194938532959157" rgba="100 0 0 0.5" density="1000" pos="0 -0.17194938532959156 0" euler="1.5707963267948966 0 0"/>
              <joint name="morphology/right_pectoral_fin_segment_1_x_axis" class="morphology/" type="hinge" axis="1 0 0" limited="true" stiffness="0.5" range="-1.5707963267948966 1.5707963267948966" damping="0.5"/>
              <joint name="morphology/right_pectoral_fin_segment_1_z_axis" class="morphology/" type="hinge" axis="0 0 1" limited="true" stiffness="0.5" range="-0.078539816339744828 0.078539816339744828" damping="0.5"/>
              <site name="morphology/right_pectoral_fin_segment_1_tendon_site" class="morphology/" type="sphere" size="0.0001 0.0001 0.0001" pos="0 -0.17194938532959156 0" euler="0 0 0"/>
            </body>
            <body name="morphology/right_pectoral_fin_segment_2" pos="0.13333333333333333 0 0" euler="0 0 0">
              <geom name="morphology/right_pectoral_fin_segment_2_capsule" class="morphology/" type="capsule" size="0.02 0.12284142322223159" rgba="100 0 0 0.5" density="1000" pos="0 -0.14284142322223159 0" euler="1.5707963267948966 0 0"/>
              <joint name="morphology/right_pectoral_fin_segment_2_x_axis" class="morphology/" type="hinge" axis="1 0 0" limited="true" stiffness="0.5" range="-1.5707963267948966 1.5707963267948966" damping="0.5"/>
              <joint name="morphology/right_pectoral_fin_segment_2_z_axis" class="morphology/" type="hinge" axis="0 0 1" limited="true" stiffness="0.5" range="-0.078539816339744828 0.078539816339744828" damping="0.5"/>
              <site name="morphology/right_pectoral_fin_segment_2_tendon_site" class="morphology/" type="sphere" size="0.0001 0.0001 0.0001" pos="0 -0.14284142322223159 0" euler="0 0 0"/>
            </body>
            <body name="morphology/right_pectoral_fin_segment_3" pos="0.17777777777777778 0 0" euler="0 0 0">
              <geom name="morphology/right_pectoral_fin_segment_3_capsule" class="morphology/" type="capsule" size="0.02 0.10050609833218532" rgba="100 0 0 0.5" density="1000" pos="0 -0.12050609833218533 0" euler="1.5707963267948966 0 0"/>
              <joint name="morphology/right_pectoral_fin_segment_3_x_axis" class="morphology/" type="hinge" axis="1 0 0" limited="true" stiffness="0.5" range="-1.5707963267948966 1.5707963267948966" damping="0.5"/>
              <joint name="morphology/right_pectoral_fin_segment_3_z_axis" class="morphology/" type="hinge" axis="0 0 1" limited="true" stiffness="0.5" range="-0.078539816339744828 0.078539816339744828" damping="0.5"/>
              <site name="morphology/right_pectoral_fin_segment_3_tendon_site" class="morphology/" type="sphere" size="0.0001 0.0001 0.0001" pos="0 -0.12050609833218533 0" euler="0 0 0"/>
            </body>
            <body name="morphology/right_pectoral_fin_segment_4" pos="0.22222222222222224 0 0" euler="0 0 0">
              <geom name="morphology/right_pectoral_fin_segment_4_capsule" class="morphology/" type="capsule" size="0.02 0.081676548436960927" rgba="100 0 0 0.5" density="1000" pos="0 -0.10167654843696093 0" euler="1.5707963267948966 0 0"/>
              <joint name="morphology/right_pectoral_fin_segment_4_x_axis" class="morphology/" type="hinge" axis="1 0 0" limited="true" stiffness="0.5" range="-1.5707963267948966 1.5707963267948966" damping="0.5"/>
              <joint name="morphology/right_pectoral_fin_segment_4_z_axis" class="morphology/" type="hinge" axis="0 0 1" limited="true" stiffness="0.5" range="-0.078539816339744828 0.078539816339744828" damping="0.5"/>
              <site name="morphology/right_pectoral_fin_segment_4_tendon_site" class="morphology/" type="sphere" size="0.0001 0.0001 0.0001" pos="0 -0.10167654843696093 0" euler="0 0 0"/>
            </body>
            <body name="morphology/right_pectoral_fin_segment_5" pos="0.26666666666666666 0 0" euler="0 0 0">
              <geom name="morphology/right_pectoral_fin_segment_5_capsule" class="morphology/" type="capsule" size="0.02 0.065087381958544993" rgba="100 0 0 0.5" density="1000" pos="0 -0.085087381958544997 0" euler="1.5707963267948966 0 0"/>
              <joint name="morphology/right_pectoral_fin_segment_5_x_axis" class="morphology/" type="hinge" axis="1 0 0" limited="true" stiffness="0.5" range="-1.5707963267948966 1.5707963267948966" damping="0.5"/>
              <joint name="morphology/right_pectoral_fin_segment_5_z_axis" class="morphology/" type="hinge" axis="0 0 1" limited="true" stiffness="0.5" range="-0.078539816339744828 0.078539816339744828" damping="0.5"/>
              <site name="morphology/right_pectoral_fin_segment_5_tendon_site" class="morphology/" type="sphere" size="0.0001 0.0001 0.0001" pos="0 -0.085087381958544997 0" euler="0 0 0"/>
            </body>
            <body name="morphology/right_pectoral_fin_segment_6" pos="0.31111111111111112 0 0" euler="0 0 0">
              <geom name="morphology/right_pectoral_fin_segment_6_capsule" class="morphology/" type="capsule" size="0.02 0.050089629057448126" rgba="100 0 0 0.5" density="1000" pos="0 -0.07008962905744813 0" euler="1.5707963267948966 0 0"/>
              <joint name="morphology/right_pectoral_fin_segment_6_x_axis" class="morphology/" type="hinge" axis="1 0 0" limited="true" stiffness="0.5" range="-1.5707963267948966 1.5707963267948966" damping="0.5"/>
              <joint name="morphology/right_pectoral_fin_segment_6_z_axis" class="morphology/" type="hinge" axis="0 0 1" limited="true" stiffness="0.5" range="-0.078539816339744828 0.078539816339744828" damping="0.5"/>
              <site name="morphology/right_pectoral_fin_segment_6_tendon_site" class="morphology/" type="sphere" size="0.0001 0.0001 0.0001" pos="0 -0.07008962905744813 0" euler="0 0 0"/>
            </body>
            <body name="morphology/right_pectoral_fin_segment_7" pos="0.35555555555555557 0 0" euler="0 0 0">
              <geom name="morphology/right_pectoral_fin_segment_7_capsule" class="morphology/" type="capsule" size="0.02 0.036297771881316554" rgba="100 0 0 0.5" density="1000" pos="0 -0.056297771881316558 0" euler="1.5707963267948966 0 0"/>
              <joint name="morphology/right_pectoral_fin_segment_7_x_axis" class="morphology/" type="hinge" axis="1 0 0" limited="true" stiffness="0.5" range="-1.5707963267948966 1.5707963267948966" damping="0.5"/>
              <joint name="morphology/right_pectoral_fin_segment_7_z_axis" class="morphology/" type="hinge" axis="0 0 1" limited="true" stiffness="0.5" range="-0.078539816339744828 0.078539816339744828" damping="0.5"/>
              <site name="morphology/right_pectoral_fin_segment_7_tendon_site" class="morphology/" type="sphere" size="0.0001 0.0001 0.0001" pos="0 -0.056297771881316558 0" euler="0 0 0"/>
            </body>
            <body name="morphology/right_pectoral_fin_segment_8" pos="0.40000000000000002 0 0" euler="0 0 0">
              <geom name="morphology/right_pectoral_fin_segment_8_capsule" class="morphology/" type="capsule" size="0.02 0.023460624222240933" rgba="100 0 0 0.5" density="1000" pos="0 -0.043460624222240937 0" euler="1.5707963267948966 0 0"/>
              <joint name="morphology/right_pectoral_fin_segment_8_x_axis" class="morphology/" type="hinge" axis="1 0 0" limited="true" stiffness="0.5" range="-1.5707963267948966 1.5707963267948966" damping="0.5"/>
              <joint name="morphology/right_pectoral_fin_segment_8_z_axis" class="morphology/" type="hinge" axis="0 0 1" limited="true" stiffness="0.5" range="-0.078539816339744828 0.078539816339744828" damping="0.5"/>
              <site name="morphology/right_pectoral_fin_segment_8_tendon_site" class="morphology/" type="sphere" size="0.0001 0.0001 0.0001" pos="0 -0.043460624222240937 0" euler="0 0 0"/>
            </body>
            <body name="morphology/right_pectoral_fin_segment_9" pos="0.44444444444444448 0 0" euler="0 0 0">
              <geom name="morphology/right_pectoral_fin_segment_9_capsule" class="morphology/" type="capsule" size="0.02 0.011403711544330286" rgba="100 0 0 0.5" density="1000" pos="0 -0.03140371154433029 0" euler="1.5707963267948966 0 0"/>
              <joint name="morphology/right_pectoral_fin_segment_9_x_axis" class="morphology/" type="hinge" axis="1 0 0" limited="true" stiffness="0.5" range="-1.5707963267948966 1.5707963267948966" damping="0.5"/>
              <joint name="morphology/right_pectoral_fin_segment_9_z_axis" class="morphology/" type="hinge" axis="0 0 1" limited="true" stiffness="0.5" range="-0.078539816339744828 0.078539816339744828" damping="0.5"/>
              <site name="morphology/right_pectoral_fin_segment_9_tendon_site" class="morphology/" type="sphere" size="0.0001 0.0001 0.0001" pos="0 -0.03140371154433029 0" euler="0 0 0"/>
            </body>
          </body>
          <body name="morphology/left_pectoral_fin" pos="-0.22222222222222224 0.11111111111111112 0" euler="0 0 0">
            <body name="morphology/left_pectoral_fin_segment_0" pos="0.044444444444444446 0 0" euler="0 0 0">
              <geom name="morphology/left_pectoral_fin_segment_0_capsule" class="morphology/" type="capsule" size="0.02 0.22222222222222224" rgba="100 0 0 0.5" density="1000" pos="0 0.24222222222222223 0" euler="1.5707963267948966 0 0"/>
              <joint name="morphology/left_pectoral_fin_segment_0_x_axis" class="morphology/" type="hinge" axis="1 0 0" limited="true" stiffness="0.5" range="-1.5707963267948966 1.5707963267948966" damping="0.5"/>
              <joint name="morphology/left_pectoral_fin_segment_0_z_axis" class="morphology/" type="hinge" axis="0 0 1" limited="true" stiffness="0.5" range="-0.078539816339744828 0.078539816339744828" damping="0.5"/>
              <site name="morphology/left_pectoral_fin_segment_0_tendon_site" class="morphology/" type="sphere" size="0.0001 0.0001 0.0001" pos="0 0.24222222222222223 0" euler="0 0 0"/>
            </body>
            <body name="morphology/left_pectoral_fin_segment_1" pos="0.088888888888888892 0 0" euler="0 0 0">
              <geom name="morphology/left_pectoral_fin_segment_1_capsule" class="morphology/" type="capsule" size="0.02 0.15194938532959157" rgba="100 0 0 0.5" density="1000" pos="0 0.17194938532959156 0" euler="1.5707963267948966 0 0"/>
              <joint name="morphology/left_pectoral_fin_segment_1_x_axis" class="morphology/" type="hinge" axis="1 0 0" limited="true" stiffness="0.5" range="-1.5707963267948966 1.5707963267948966" damping="0.5"/>
              <joint name="morphology/left_pectoral_fin_segment_1_z_axis" class="morphology/" type="hinge" axis="0 0 1" limited="true" stiffness="0.5" range="-0.078539816339744828 0.078539816339744828" damping="0.5"/>
              <site name="morphology/left_pectoral_fin_segment_1_tendon_site" class="morphology/" type="sphere" size="0.0001 0.0001 0.0001" pos="0 0.17194938532959156 0" euler="0 0 0"/>
            </body>
            <body name="morphology/left_pectoral_fin_segment_2" pos="0.13333333333333333 0 0" euler="0 0 0">
              <geom name="morphology/left_pectoral_fin_segment_2_capsule" class="morphology/" type="capsule" size="0.02 0.12284142322223159" rgba="100 0 0 0.5" density="1000" pos="0 0.14284142322223159 0" euler="1.5707963267948966 0 0"/>
              <joint name="morphology/left_pectoral_fin_segment_2_x_axis" class="morphology/" type="hinge" axis="1 0 0" limited="true" stiffness="0.5" range="-1.5707963267948966 1.5707963267948966" damping="0.5"/>
              <joint name="morphology/left_pectoral_fin_segment_2_z_axis" class="morphology/" type="hinge" axis="0 0 1" limited="true" stiffness="0.5" range="-0.078539816339744828 0.078539816339744828" damping="0.5"/>
              <site name="morphology/left_pectoral_fin_segment_2_tendon_site" class="morphology/" type="sphere" size="0.0001 0.0001 0.0001" pos="0 0.14284142322223159 0" euler="0 0 0"/>
            </body>
            <body name="morphology/left_pectoral_fin_segment_3" pos="0.17777777777777778 0 0" euler="0 0 0">
              <geom name="morphology/left_pectoral_fin_segment_3_capsule" class="morphology/" type="capsule" size="0.02 0.10050609833218532" rgba="100 0 0 0.5" density="1000" pos="0 0.12050609833218533 0" euler="1.5707963267948966 0 0"/>
              <joint name="morphology/left_pectoral_fin_segment_3_x_axis" class="morphology/" type="hinge" axis="1 0 0" limited="true" stiffness="0.5" range="-1.5707963267948966 1.5707963267948966" damping="0.5"/>
              <joint name="morphology/left_pectoral_fin_segment_3_z_axis" class="morphology/" type="hinge" axis="0 0 1" limited="true" stiffness="0.5" range="-0.078539816339744828 0.078539816339744828" damping="0.5"/>
              <site name="morphology/left_pectoral_fin_segment_3_tendon_site" class="morphology/" type="sphere" size="0.0001 0.0001 0.0001" pos="0 0.12050609833218533 0" euler="0 0 0"/>
            </body>
            <body name="morphology/left_pectoral_fin_segment_4" pos="0.22222222222222224 0 0" euler="0 0 0">
              <geom name="morphology/left_pectoral_fin_segment_4_capsule" class="morphology/" type="capsule" size="0.02 0.081676548436960927" rgba="100 0 0 0.5" density="1000" pos="0 0.10167654843696093 0" euler="1.5707963267948966 0 0"/>
              <joint name="morphology/left_pectoral_fin_segment_4_x_axis" class="morphology/" type="hinge" axis="1 0 0" limited="true" stiffness="0.5" range="-1.5707963267948966 1.5707963267948966" damping="0.5"/>
              <joint name="morphology/left_pectoral_fin_segment_4_z_axis" class="morphology/" type="hinge" axis="0 0 1" limited="true" stiffness="0.5" range="-0.078539816339744828 0.078539816339744828" damping="0.5"/>
              <site name="morphology/left_pectoral_fin_segment_4_tendon_site" class="morphology/" type="sphere" size="0.0001 0.0001 0.0001" pos="0 0.10167654843696093 0" euler="0 0 0"/>
            </body>
            <body name="morphology/left_pectoral_fin_segment_5" pos="0.26666666666666666 0 0" euler="0 0 0">
              <geom name="morphology/left_pectoral_fin_segment_5_capsule" class="morphology/" type="capsule" size="0.02 0.065087381958544993" rgba="100 0 0 0.5" density="1000" pos="0 0.085087381958544997 0" euler="1.5707963267948966 0 0"/>
              <joint name="morphology/left_pectoral_fin_segment_5_x_axis" class="morphology/" type="hinge" axis="1 0 0" limited="true" stiffness="0.5" range="-1.5707963267948966 1.5707963267948966" damping="0.5"/>
              <joint name="morphology/left_pectoral_fin_segment_5_z_axis" class="morphology/" type="hinge" axis="0 0 1" limited="true" stiffness="0.5" range="-0.078539816339744828 0.078539816339744828" damping="0.5"/>
              <site name="morphology/left_pectoral_fin_segment_5_tendon_site" class="morphology/" type="sphere" size="0.0001 0.0001 0.0001" pos="0 0.085087381958544997 0" euler="0 0 0"/>
            </body>
            <body name="morphology/left_pectoral_fin_segment_6" pos="0.31111111111111112 0 0" euler="0 0 0">
              <geom name="morphology/left_pectoral_fin_segment_6_capsule" class="morphology/" type="capsule" size="0.02 0.050089629057448126" rgba="100 0 0 0.5" density="1000" pos="0 0.07008962905744813 0" euler="1.5707963267948966 0 0"/>
              <joint name="morphology/left_pectoral_fin_segment_6_x_axis" class="morphology/" type="hinge" axis="1 0 0" limited="true" stiffness="0.5" range="-1.5707963267948966 1.5707963267948966" damping="0.5"/>
              <joint name="morphology/left_pectoral_fin_segment_6_z_axis" class="morphology/" type="hinge" axis="0 0 1" limited="true" stiffness="0.5" range="-0.078539816339744828 0.078539816339744828" damping="0.5"/>
              <site name="morphology/left_pectoral_fin_segment_6_tendon_site" class="morphology/" type="sphere" size="0.0001 0.0001 0.0001" pos="0 0.07008962905744813 0" euler="0 0 0"/>
            </body>
            <body name="morphology/left_pectoral_fin_segment_7" pos="0.35555555555555557 0 0" euler="0 0 0">
              <geom name="morphology/left_pectoral_fin_segment_7_capsule" class="morphology/" type="capsule" size="0.02 0.036297771881316554" rgba="100 0 0 0.5" density="1000" pos="0 0.056297771881316558 0" euler="1.5707963267948966 0 0"/>
              <joint name="morphology/left_pectoral_fin_segment_7_x_axis" class="morphology/" type="hinge" axis="1 0 0" limited="true" stiffness="0.5" range="-1.5707963267948966 1.5707963267948966" damping="0.5"/>
              <joint name="morphology/left_pectoral_fin_segment_7_z_axis" class="morphology/" type="hinge" axis="0 0 1" limited="true" stiffness="0.5" range="-0.078539816339744828 0.078539816339744828" damping="0.5"/>
              <site name="morphology/left_pectoral_fin_segment_7_tendon_site" class="morphology/" type="sphere" size="0.0001 0.0001 0.0001" pos="0 0.056297771881316558 0" euler="0 0 0"/>
            </body>
            <body name="morphology/left_pectoral_fin_segment_8" pos="0.40000000000000002 0 0" euler="0 0 0">
              <geom name="morphology/left_pectoral_fin_segment_8_capsule" class="morphology/" type="capsule" size="0.02 0.023460624222240933" rgba="100 0 0 0.5" density="1000" pos="0 0.043460624222240937 0" euler="1.5707963267948966 0 0"/>
              <joint name="morphology/left_pectoral_fin_segment_8_x_axis" class="morphology/" type="hinge" axis="1 0 0" limited="true" stiffness="0.5" range="-1.5707963267948966 1.5707963267948966" damping="0.5"/>
              <joint name="morphology/left_pectoral_fin_segment_8_z_axis" class="morphology/" type="hinge" axis="0 0 1" limited="true" stiffness="0.5" range="-0.078539816339744828 0.078539816339744828" damping="0.5"/>
              <site name="morphology/left_pectoral_fin_segment_8_tendon_site" class="morphology/" type="sphere" size="0.0001 0.0001 0.0001" pos="0 0.043460624222240937 0" euler="0 0 0"/>
            </body>
            <body name="morphology/left_pectoral_fin_segment_9" pos="0.44444444444444448 0 0" euler="0 0 0">
              <geom name="morphology/left_pectoral_fin_segment_9_capsule" class="morphology/" type="capsule" size="0.02 0.011403711544330286" rgba="100 0 0 0.5" density="1000" pos="0 0.03140371154433029 0" euler="1.5707963267948966 0 0"/>
              <joint name="morphology/left_pectoral_fin_segment_9_x_axis" class="morphology/" type="hinge" axis="1 0 0" limited="true" stiffness="0.5" range="-1.5707963267948966 1.5707963267948966" damping="0.5"/>
              <joint name="morphology/left_pectoral_fin_segment_9_z_axis" class="morphology/" type="hinge" axis="0 0 1" limited="true" stiffness="0.5" range="-0.078539816339744828 0.078539816339744828" damping="0.5"/>
              <site name="morphology/left_pectoral_fin_segment_9_tendon_site" class="morphology/" type="sphere" size="0.0001 0.0001 0.0001" pos="0 0.03140371154433029 0" euler="0 0 0"/>
            </body>
          </body>
        </body>
        <body name="morphology/tail" pos="0.33333333333333337 0 0" euler="0 0 0">
          <body name="morphology/tail_segment_0" pos="0 0 0" euler="0 0 0">
            <geom name="morphology/tail_segment_0_capsule" class="morphology/" type="capsule" size="0.011111111111111112 0.11111111111111112" rgba="100 0 0 0.5" density="1000" pos="0.12222222222222223 0 0" euler="0 1.5707963267948966 0"/>
            <joint name="morphology/tail_segment_0_z_axis" class="morphology/" type="hinge" axis="0 0 1" limited="true" stiffness="0.01" range="-0.78539816339744828 0.78539816339744828" damping="1"/>
            <joint name="morphology/tail_segment_0_y_axis" class="morphology/" type="hinge" axis="0 1 0" limited="true" stiffness="0.01" range="-0.78539816339744828 0.78539816339744828" damping="1"/>
            <body name="morphology/tail_segment_1" pos="0.24444444444444446 0 0" euler="0 0 0">
              <geom name="morphology/tail_segment_1_capsule" class="morphology/" type="capsule" size="0.011111111111111112 0.11111111111111112" rgba="100 0 0 0.5" density="1000" pos="0.12222222222222223 0 0" euler="0 1.5707963267948966 0"/>
              <joint name="morphology/tail_segment_1_z_axis" class="morphology/" type="hinge" axis="0 0 1" limited="true" stiffness="0.01" range="-0.78539816339744828 0.78539816339744828" damping="1"/>
              <joint name="morphology/tail_segment_1_y_axis" class="morphology/" type="hinge" axis="0 1 0" limited="true" stiffness="0.01" range="-0.78539816339744828 0.78539816339744828" damping="1"/>
            </body>
          </body>
        </body>
      </body>
    </body>
  </worldbody>
  <tendon>
    <spatial name="morphology/right_pectoral_fin_tendon_right" class="morphology/" limited="true" range="-20.871032557111299 21.292669578467084" width="0.0050000000000000001" stiffness="1000" damping="1">
      <site site="morphology/right_pectoral_fin_segment_0_tendon_site"/>
      <site site="morphology/right_pectoral_fin_segment_1_tendon_site"/>
      <site site="morphology/right_pectoral_fin_segment_2_tendon_site"/>
      <site site="morphology/right_pectoral_fin_segment_3_tendon_site"/>
      <site site="morphology/right_pectoral_fin_segment_4_tendon_site"/>
      <site site="morphology/right_pectoral_fin_segment_5_tendon_site"/>
      <site site="morphology/right_pectoral_fin_segment_6_tendon_site"/>
      <site site="morphology/right_pectoral_fin_segment_7_tendon_site"/>
      <site site="morphology/right_pectoral_fin_segment_8_tendon_site"/>
      <site site="morphology/right_pectoral_fin_segment_9_tendon_site"/>
    </spatial>
    <spatial name="morphology/left_pectoral_fin_tendon_left" class="morphology/" limited="true" range="-20.871032557111299 21.292669578467084" width="0.0050000000000000001" stiffness="1000" damping="1">
      <site site="morphology/left_pectoral_fin_segment_0_tendon_site"/>
      <site site="morphology/left_pectoral_fin_segment_1_tendon_site"/>
      <site site="morphology/left_pectoral_fin_segment_2_tendon_site"/>
      <site site="morphology/left_pectoral_fin_segment_3_tendon_site"/>
      <site site="morphology/left_pectoral_fin_segment_4_tendon_site"/>
      <site site="morphology/left_pectoral_fin_segment_5_tendon_site"/>
      <site site="morphology/left_pectoral_fin_segment_6_tendon_site"/>
      <site site="morphology/left_pectoral_fin_segment_7_tendon_site"/>
      <site site="morphology/left_pectoral_fin_segment_8_tendon_site"/>
      <site site="morphology/left_pectoral_fin_segment_9_tendon_site"/>
    </spatial>
  </tendon>
  <actuator>
    <position name="morphology/tail_segment_0_z_axis_actuator" class="morphology/" ctrllimited="true" ctrlrange="-0.78539816339744828 0.78539816339744828" joint="morphology/tail_segment_0_z_axis" kp="100"/>
    <position name="morphology/tail_segment_0_y_axis_actuator" class="morphology/" ctrllimited="true" ctrlrange="-0.78539816339744828 0.78539816339744828" joint="morphology/tail_segment_0_y_axis" kp="100"/>
    <position name="morphology/tail_segment_1_z_axis_actuator" class="morphology/" ctrllimited="true" ctrlrange="-0.78539816339744828 0.78539816339744828" joint="morphology/tail_segment_1_z_axis" kp="100"/>
    <position name="morphology/tail_segment_1_y_axis_actuator" class="morphology/" ctrllimited="true" ctrlrange="-0.78539816339744828 0.78539816339744828" joint="morphology/tail_segment_1_y_axis" kp="100"/>
    <position name="morphology/right_pectoral_fin_actuator_x" class="morphology/" ctrllimited="true" ctrlrange="-1.5707963267948966 1.5707963267948966" joint="morphology/right_pectoral_fin_segment_0_x_axis" kp="100"/>
    <position name="morphology/right_pectoral_fin_actuator_z" class="morphology/" ctrllimited="true" ctrlrange="-1.5707963267948966 1.5707963267948966" joint="morphology/right_pectoral_fin_segment_0_z_axis" kp="100"/>
    <position name="morphology/left_pectoral_fin_actuator_x" class="morphology/" ctrllimited="true" ctrlrange="-1.5707963267948966 1.5707963267948966" joint="morphology/left_pectoral_fin_segment_0_x_axis" kp="100"/>
    <position name="morphology/left_pectoral_fin_actuator_z" class="morphology/" ctrllimited="true" ctrlrange="-1.5707963267948966 1.5707963267948966" joint="morphology/left_pectoral_fin_segment_0_z_axis" kp="100"/>
  </actuator>
  <sensor>
    <actuatorfrc name="morphology/right_pectoral_fin_force_sensor_x" actuator="morphology/right_pectoral_fin_actuator_x"/>
    <actuatorfrc name="morphology/right_pectoral_fin_force_sensor_z" actuator="morphology/right_pectoral_fin_actuator_z"/>
    <actuatorfrc name="morphology/left_pectoral_fin_force_sensor_x" actuator="morphology/left_pectoral_fin_actuator_x"/>
    <actuatorfrc name="morphology/left_pectoral_fin_force_sensor_z" actuator="morphology/left_pectoral_fin_actuator_z"/>
  </sensor>
</mujoco>
